Workbook

Sheet Inputs
A1: Scenario｜场景 | B1: Value｜值
A2: Scenario selection｜选择场景 | B2: C&I
A4: Client/Project｜客户/项目 | B4: =IFERROR(VLOOKUP($B$2,Scenarios!$A$2:$O$200,2,FALSE),"") -> ACME Solar Munich 10MW
A5: Region｜区域 | B5: =IFERROR(VLOOKUP($B$2,Scenarios!$A$2:$O$200,3,FALSE),"") -> Germany
A6: Date｜日期 | B6: =IFERROR(VLOOKUP($B$2,Scenarios!$A$2:$O$200,4,FALSE),"") -> 2025-09-10
A7: Notes｜备注 | B7: =IFERROR(VLOOKUP($B$2,Scenarios!$A$2:$O$200,15,FALSE),"") -> Proposal for Munich industrial site
A9: Parameter｜参数 | B9: Value｜值 (auto from Scenario)
A10: Plant size (MW)｜电站规模 | B10: =VLOOKUP($B$2,Scenarios!$A$2:$O$200,5,FALSE) -> 10
A11: Cleaning frequency (times/year)｜清洗频次 | B11: =VLOOKUP($B$2,Scenarios!$A$2:$O$200,6,FALSE) -> 6
A12: Manual cleaning cost ($/MW per cleaning)｜人工清洗单价 | B12: =VLOOKUP($B$2,Scenarios!$A$2:$O$200,7,FALSE) -> 1500
A13: Soiling improvement (%)｜污损改善率(%) | B13: =VLOOKUP($B$2,Scenarios!$A$2:$O$200,8,FALSE) -> 3
A14: Electricity price ($/kWh)｜上网电价 | B14: =VLOOKUP($B$2,Scenarios!$A$2:$O$200,9,FALSE) -> 0.2
A15: Capacity factor (%)｜容量系数 | B15: =VLOOKUP($B$2,Scenarios!$A$2:$O$200,10,FALSE) -> 17
A16: Cleaning window per cycle (days)｜每周期施工窗 | B16: =VLOOKUP($B$2,Scenarios!$A$2:$O$200,11,FALSE) -> 7
A17: Shifts per day (1=single, 2=day+night)｜班次数 | B17: =VLOOKUP($B$2,Scenarios!$A$2:$O$200,12,FALSE) -> 1
A18: Redundancy factor (e.g., 1.1)｜冗余系数 | B18: =VLOOKUP($B$2,Scenarios!$A$2:$O$200,13,FALSE) -> 1.1
A19: Analysis horizon (years)｜测算年限 | B19: =VLOOKUP($B$2,Scenarios!$A$2:$O$200,14,FALSE) -> 5

Sheet Devices
A1: Enable | B1: Device | C1: Method | D1: Unit price | E1: Capacity | F1: Consumable | G1: Interval | H1: Warranty | I1: Lifetime | J1: Units
A2: 0 | B2: NuvaTrack R | C2: Dry/Wet | D2: 3900 | E2: 2 | F2: 500 | G2: 6 | H2: 390 | I2: 5 | J2: 1
A3: 1 | B3: NuvaTrack U | C3: Dry | D3: 11900 | E3: 1 | F3: 500 | G3: 6 | H3: 1190 | I3: 5 | J3: 2
A4: 0 | B4: NuvaSpan | C4: Dry | D4: 3900 | E4: 3 | F4: 500 | G4: 6 | H4: 390 | I4: 5 | J4: 5
A5: 0 | B5: Gantry G1 | C5: Dry | D5: 119000 | E5: 0.6 | F5: 1500 | G5: 6 | H5: 1190 | I5: 5 | J5: 0

Sheet Summary
A1: Total capacity | B1: Adequacy | C1: Annual manual cost | D1: Annual robot cost | E1: Annual savings | F1: CAPEX | G1: Payback year | H1: ROI | I1: Annual generation | J1: Extra revenue
A2: =SUMPRODUCT(Devices!$A$2:$A$4,Devices!$J$2:$J$4,Devices!$E$2:$E$4)*Inputs!B17*Inputs!B16 -> 14 | B2: =IF(Summary!A2>=Inputs!B10*Inputs!B18,"Yes","No") -> Yes | C2: =Inputs!B10*Inputs!B11*Inputs!B12 -> 90000 | D2: =SUMPRODUCT(Devices!$A$2:$A$4,Devices!$J$2:$J$4,(Devices!$D$2:$D$4/Devices!$I$2:$I$4+12/Devices!$G$2:$G$4*Devices!$F$2:$F$4+Devices!$H$2:$H$4)) -> 9140 | E2: =Summary!C2-Summary!D2 -> 80860 | F2: =SUMPRODUCT(Devices!$A$2:$A$4,Devices!$J$2:$J$4,Devices!$D$2:$D$4) -> 23800 | G2: =IFERROR(INDEX(Yearly!A2:A31,MATCH(TRUE,Yearly!G2:G31,0)),"N/A") -> 1 | H2: =IFERROR((INDEX(Yearly!E2:E31,Inputs!B19)-Summary!F2)/Summary!F2,"N/A") -> 15.987395 | I2: =Inputs!B10*1000*8760*(Inputs!B15/100) -> 14892000 | J2: =Summary!I2*Inputs!B14*(Inputs!B13/100) -> 89352

Sheet Yearly
A1: Year | B1: Manual | C1: Robot | D1: Savings | E1: Cum savings | F1: CAPEX | G1: Cum>=CAPEX? | H1: Cum+Revenue
A2: =IF(1<=Inputs!B19,1,"") -> 1 | B2: =IF($A2<>"",Summary!C2,"") -> 90000 | C2: =IF($A2<>"",Summary!D2,"") -> 9140 | D2: =IF($A2<>"",B2-C2,"") -> 80860 | E2: =IF($A2<>"",D2,"") -> 80860 | F2: =IF($A2<>"",Summary!F2,"") -> 23800 | G2: =IF($A2<>"",E2>=F2,"") -> TRUE | H2: =IF($A2<>"",E2+Summary!J2*A2,"") -> 170212
A3: =IF(2<=Inputs!B19,2,"") -> 2 | B3: =IF($A3<>"",Summary!C2,"") -> 90000 | C3: =IF($A3<>"",Summary!D2,"") -> 9140 | D3: =IF($A3<>"",B3-C3,"") -> 80860 | E3: =IF($A3<>"",E2+D3,"") -> 161720 | F3: =IF($A3<>"",Summary!F2,"") -> 23800 | G3: =IF($A3<>"",E3>=F3,"") -> TRUE | H3: =IF($A3<>"",E3+Summary!J2*A3,"") -> 340424
A4: =IF(3<=Inputs!B19,3,"") -> 3 | B4: =IF($A4<>"",Summary!C2,"") -> 90000 | C4: =IF($A4<>"",Summary!D2,"") -> 9140 | D4: =IF($A4<>"",B4-C4,"") -> 80860 | E4: =IF($A4<>"",E3+D4,"") -> 242580 | F4: =IF($A4<>"",Summary!F2,"") -> 23800 | G4: =IF($A4<>"",E4>=F4,"") -> TRUE | H4: =IF($A4<>"",E4+Summary!J2*A4,"") -> 510636
A5: =IF(4<=Inputs!B19,4,"") -> 4 | B5: =IF($A5<>"",Summary!C2,"") -> 90000 | C5: =IF($A5<>"",Summary!D2,"") -> 9140 | D5: =IF($A5<>"",B5-C5,"") -> 80860 | E5: =IF($A5<>"",E4+D5,"") -> 323440 | F5: =IF($A5<>"",Summary!F2,"") -> 23800 | G5: =IF($A5<>"",E5>=F5,"") -> TRUE | H5: =IF($A5<>"",E5+Summary!J2*A5,"") -> 680848
A6: =IF(5<=Inputs!B19,5,"") -> 5 | B6: =IF($A6<>"",Summary!C2,"") -> 90000 | C6: =IF($A6<>"",Summary!D2,"") -> 9140 | D6: =IF($A6<>"",B6-C6,"") -> 80860 | E6: =IF($A6<>"",E5+D6,"") -> 404300 | F6: =IF($A6<>"",Summary!F2,"") -> 23800 | G6: =IF($A6<>"",E6>=F6,"") -> TRUE | H6: =IF($A6<>"",E6+Summary!J2*A6,"") -> 851060
A7: =IF(6<=Inputs!B19,6,"") | B7: =IF($A7<>"",Summary!C2,"") | C7: =IF($A7<>"",Summary!D2,"") | D7: =IF($A7<>"",B7-C7,"") | E7: =IF($A7<>"",E6+D7,"") | F7: =IF($A7<>"",Summary!F2,"") | G7: =IF($A7<>"",E7>=F7,"") | H7: =IF($A7<>"",E7+Summary!J2*A7,"")
A8: =IF(7<=Inputs!B19,7,"") | B8: =IF($A8<>"",Summary!C2,"") | C8: =IF($A8<>"",Summary!D2,"") | D8: =IF($A8<>"",B8-C8,"") | E8: =IF($A8<>"",E7+D8,"") | F8: =IF($A8<>"",Summary!F2,"") | G8: =IF($A8<>"",E8>=F8,"") | H8: =IF($A8<>"",E8+Summary!J2*A8,"")
A9: =IF(8<=Inputs!B19,8,"") | B9: =IF($A9<>"",Summary!C2,"") | C9: =IF($A9<>"",Summary!D2,"") | D9: =IF($A9<>"",B9-C9,"") | E9: =IF($A9<>"",E8+D9,"") | F9: =IF($A9<>"",Summary!F2,"") | G9: =IF($A9<>"",E9>=F9,"") | H9: =IF($A9<>"",E9+Summary!J2*A9,"")
A10: =IF(9<=Inputs!B19,9,"") | B10: =IF($A10<>"",Summary!C2,"") | C10: =IF($A10<>"",Summary!D2,"") | D10: =IF($A10<>"",B10-C10,"") | E10: =IF($A10<>"",E9+D10,"") | F10: =IF($A10<>"",Summary!F2,"") | G10: =IF($A10<>"",E10>=F10,"") | H10: =IF($A10<>"",E10+Summary!J2*A10,"")
A11: =IF(10<=Inputs!B19,10,"") | B11: =IF($A11<>"",Summary!C2,"") | C11: =IF($A11<>"",Summary!D2,"") | D11: =IF($A11<>"",B11-C11,"") | E11: =IF($A11<>"",E10+D11,"") | F11: =IF($A11<>"",Summary!F2,"") | G11: =IF($A11<>"",E11>=F11,"") | H11: =IF($A11<>"",E11+Summary!J2*A11,"")
A12: =IF(11<=Inputs!B19,11,"") | B12: =IF($A12<>"",Summary!C2,"") | C12: =IF($A12<>"",Summary!D2,"") | D12: =IF($A12<>"",B12-C12,"") | E12: =IF($A12<>"",E11+D12,"") | F12: =IF($A12<>"",Summary!F2,"") | G12: =IF($A12<>"",E12>=F12,"") | H12: =IF($A12<>"",E12+Summary!J2*A12,"")
A13: =IF(12<=Inputs!B19,12,"") | B13: =IF($A13<>"",Summary!C2,"") | C13: =IF($A13<>"",Summary!D2,"") | D13: =IF($A13<>"",B13-C13,"") | E13: =IF($A13<>"",E12+D13,"") | F13: =IF($A13<>"",Summary!F2,"") | G13: =IF($A13<>"",E13>=F13,"") | H13: =IF($A13<>"",E13+Summary!J2*A13,"")
A14: =IF(13<=Inputs!B19,13,"") | B14: =IF($A14<>"",Summary!C2,"") | C14: =IF($A14<>"",Summary!D2,"") | D14: =IF($A14<>"",B14-C14,"") | E14: =IF($A14<>"",E13+D14,"") | F14: =IF($A14<>"",Summary!F2,"") | G14: =IF($A14<>"",E14>=F14,"") | H14: =IF($A14<>"",E14+Summary!J2*A14,"")
A15: =IF(14<=Inputs!B19,14,"") | B15: =IF($A15<>"",Summary!C2,"") | C15: =IF($A15<>"",Summary!D2,"") | D15: =IF($A15<>"",B15-C15,"") | E15: =IF($A15<>"",E14+D15,"") | F15: =IF($A15<>"",Summary!F2,"") | G15: =IF($A15<>"",E15>=F15,"") | H15: =IF($A15<>"",E15+Summary!J2*A15,"")
A16: =IF(15<=Inputs!B19,15,"") | B16: =IF($A16<>"",Summary!C2,"") | C16: =IF($A16<>"",Summary!D2,"") | D16: =IF($A16<>"",B16-C16,"") | E16: =IF($A16<>"",E15+D16,"") | F16: =IF($A16<>"",Summary!F2,"") | G16: =IF($A16<>"",E16>=F16,"") | H16: =IF($A16<>"",E16+Summary!J2*A16,"")
A17: =IF(16<=Inputs!B19,16,"") | B17: =IF($A17<>"",Summary!C2,"") | C17: =IF($A17<>"",Summary!D2,"") | D17: =IF($A17<>"",B17-C17,"") | E17: =IF($A17<>"",E16+D17,"") | F17: =IF($A17<>"",Summary!F2,"") | G17: =IF($A17<>"",E17>=F17,"") | H17: =IF($A17<>"",E17+Summary!J2*A17,"")
A18: =IF(17<=Inputs!B19,17,"") | B18: =IF($A18<>"",Summary!C2,"") | C18: =IF($A18<>"",Summary!D2,"") | D18: =IF($A18<>"",B18-C18,"") | E18: =IF($A18<>"",E17+D18,"") | F18: =IF($A18<>"",Summary!F2,"") | G18: =IF($A18<>"",E18>=F18,"") | H18: =IF($A18<>"",E18+Summary!J2*A18,"")
A19: =IF(18<=Inputs!B19,18,"") | B19: =IF($A19<>"",Summary!C2,"") | C19: =IF($A19<>"",Summary!D2,"") | D19: =IF($A19<>"",B19-C19,"") | E19: =IF($A19<>"",E18+D19,"") | F19: =IF($A19<>"",Summary!F2,"") | G19: =IF($A19<>"",E19>=F19,"") | H19: =IF($A19<>"",E19+Summary!J2*A19,"")
A20: =IF(19<=Inputs!B19,19,"") | B20: =IF($A20<>"",Summary!C2,"") | C20: =IF($A20<>"",Summary!D2,"") | D20: =IF($A20<>"",B20-C20,"") | E20: =IF($A20<>"",E19+D20,"") | F20: =IF($A20<>"",Summary!F2,"") | G20: =IF($A20<>"",E20>=F20,"") | H20: =IF($A20<>"",E20+Summary!J2*A20,"")
A21: =IF(20<=Inputs!B19,20,"") | B21: =IF($A21<>"",Summary!C2,"") | C21: =IF($A21<>"",Summary!D2,"") | D21: =IF($A21<>"",B21-C21,"") | E21: =IF($A21<>"",E20+D21,"") | F21: =IF($A21<>"",Summary!F2,"") | G21: =IF($A21<>"",E21>=F21,"") | H21: =IF($A21<>"",E21+Summary!J2*A21,"")
A22: =IF(21<=Inputs!B19,21,"") | B22: =IF($A22<>"",Summary!C2,"") | C22: =IF($A22<>"",Summary!D2,"") | D22: =IF($A22<>"",B22-C22,"") | E22: =IF($A22<>"",E21+D22,"") | F22: =IF($A22<>"",Summary!F2,"") | G22: =IF($A22<>"",E22>=F22,"") | H22: =IF($A22<>"",E22+Summary!J2*A22,"")
A23: =IF(22<=Inputs!B19,22,"") | B23: =IF($A23<>"",Summary!C2,"") | C23: =IF($A23<>"",Summary!D2,"") | D23: =IF($A23<>"",B23-C23,"") | E23: =IF($A23<>"",E22+D23,"") | F23: =IF($A23<>"",Summary!F2,"") | G23: =IF($A23<>"",E23>=F23,"") | H23: =IF($A23<>"",E23+Summary!J2*A23,"")
A24: =IF(23<=Inputs!B19,23,"") | B24: =IF($A24<>"",Summary!C2,"") | C24: =IF($A24<>"",Summary!D2,"") | D24: =IF($A24<>"",B24-C24,"") | E24: =IF($A24<>"",E23+D24,"") | F24: =IF($A24<>"",Summary!F2,"") | G24: =IF($A24<>"",E24>=F24,"") | H24: =IF($A24<>"",E24+Summary!J2*A24,"")
A25: =IF(24<=Inputs!B19,24,"") | B25: =IF($A25<>"",Summary!C2,"") | C25: =IF($A25<>"",Summary!D2,"") | D25: =IF($A25<>"",B25-C25,"") | E25: =IF($A25<>"",E24+D25,"") | F25: =IF($A25<>"",Summary!F2,"") | G25: =IF($A25<>"",E25>=F25,"") | H25: =IF($A25<>"",E25+Summary!J2*A25,"")
A26: =IF(25<=Inputs!B19,25,"") | B26: =IF($A26<>"",Summary!C2,"") | C26: =IF($A26<>"",Summary!D2,"") | D26: =IF($A26<>"",B26-C26,"") | E26: =IF($A26<>"",E25+D26,"") | F26: =IF($A26<>"",Summary!F2,"") | G26: =IF($A26<>"",E26>=F26,"") | H26: =IF($A26<>"",E26+Summary!J2*A26,"")
A27: =IF(26<=Inputs!B19,26,"") | B27: =IF($A27<>"",Summary!C2,"") | C27: =IF($A27<>"",Summary!D2,"") | D27: =IF($A27<>"",B27-C27,"") | E27: =IF($A27<>"",E26+D27,"") | F27: =IF($A27<>"",Summary!F2,"") | G27: =IF($A27<>"",E27>=F27,"") | H27: =IF($A27<>"",E27+Summary!J2*A27,"")
A28: =IF(27<=Inputs!B19,27,"") | B28: =IF($A28<>"",Summary!C2,"") | C28: =IF($A28<>"",Summary!D2,"") | D28: =IF($A28<>"",B28-C28,"") | E28: =IF($A28<>"",E27+D28,"") | F28: =IF($A28<>"",Summary!F2,"") | G28: =IF($A28<>"",E28>=F28,"") | H28: =IF($A28<>"",E28+Summary!J2*A28,"")
A29: =IF(28<=Inputs!B19,28,"") | B29: =IF($A29<>"",Summary!C2,"") | C29: =IF($A29<>"",Summary!D2,"") | D29: =IF($A29<>"",B29-C29,"") | E29: =IF($A29<>"",E28+D29,"") | F29: =IF($A29<>"",Summary!F2,"") | G29: =IF($A29<>"",E29>=F29,"") | H29: =IF($A29<>"",E29+Summary!J2*A29,"")
A30: =IF(29<=Inputs!B19,29,"") | B30: =IF($A30<>"",Summary!C2,"") | C30: =IF($A30<>"",Summary!D2,"") | D30: =IF($A30<>"",B30-C30,"") | E30: =IF($A30<>"",E29+D30,"") | F30: =IF($A30<>"",Summary!F2,"") | G30: =IF($A30<>"",E30>=F30,"") | H30: =IF($A30<>"",E30+Summary!J2*A30,"")
A31: =IF(30<=Inputs!B19,30,"") | B31: =IF($A31<>"",Summary!C2,"") | C31: =IF($A31<>"",Summary!D2,"") | D31: =IF($A31<>"",B31-C31,"") | E31: =IF($A31<>"",E30+D31,"") | F31: =IF($A31<>"",Summary!F2,"") | G31: =IF($A31<>"",E31>=F31,"") | H31: =IF($A31<>"",E31+Summary!J2*A31,"")

Sheet Dashboard
A1: Dashboard｜看板（修改 Inputs / Devices / Scenarios 自动联动）

Sheet Scenarios
A1: Scenario | B1: Client/Project | C1: Region | D1: Date | E1: Plant | F1: Freq | G1: Manual | H1: Soiling | I1: ElecPrice | J1: CapFactor | K1: Window | L1: Shifts | M1: Redundancy | N1: Horizon | O1: Notes
A2: Rooftop | B2: Demo Rooftop Case | C2: Germany | D2: 2025-09-10 | E2: 1 | F2: 2 | G2: 2000 | H2: 2 | I2: 0.2 | J2: 15 | K2: 3 | L2: 1 | M2: 1.05 | N2: 5 | O2: Default rooftop example
A3: C&I | B3: ACME Solar Munich 10MW | C3: Germany | D3: 2025-09-10 | E3: 10 | F3: 6 | G3: 1500 | H3: 3 | I3: 0.2 | J3: 17 | K3: 7 | L3: 1 | M3: 1.1 | N3: 5 | O3: Proposal for Munich industrial site
A4: Utility | B4: NEOM 200MW Desert Plant | C4: Saudi Arabia | D4: 2025-09-10 | E4: 200 | F4: 12 | G4: 1200 | H4: 4 | I4: 0.2 | J4: 23 | K4: 12 | L4: 2 | M4: 1.15 | N4: 10 | O4: Desert utility case, dry-cleaning

Sheet Sensitivity
A1: Manual↓ / Freq→ | B1: Freq=4 | C1: Freq=6 | D1: Freq=8 | E1: Freq=10 | F1: Freq=12
A2: Manual=1200 | B2: =((Inputs!B10*4*1200)-Summary!D2)*Inputs!B19/Summary!F2 -> 8.1638655 | C2: =((Inputs!B10*6*1200)-Summary!D2)*Inputs!B19/Summary!F2 -> 13.205882 | D2: =((Inputs!B10*8*1200)-Summary!D2)*Inputs!B19/Summary!F2 -> 18.247899 | E2: =((Inputs!B10*10*1200)-Summary!D2)*Inputs!B19/Summary!F2 -> 23.289916 | F2: =((Inputs!B10*12*1200)-Summary!D2)*Inputs!B19/Summary!F2 -> 28.331933
A3: Manual=1800 | B3: =((Inputs!B10*4*1800)-Summary!D2)*Inputs!B19/Summary!F2 -> 13.205882 | C3: =((Inputs!B10*6*1800)-Summary!D2)*Inputs!B19/Summary!F2 -> 20.768908 | D3: =((Inputs!B10*8*1800)-Summary!D2)*Inputs!B19/Summary!F2 -> 28.331933 | E3: =((Inputs!B10*10*1800)-Summary!D2)*Inputs!B19/Summary!F2 -> 35.894958 | F3: =((Inputs!B10*12*1800)-Summary!D2)*Inputs!B19/Summary!F2 -> 43.457983
A4: Manual=2200 | B4: =((Inputs!B10*4*2200)-Summary!D2)*Inputs!B19/Summary!F2 -> 16.567227 | C4: =((Inputs!B10*6*2200)-Summary!D2)*Inputs!B19/Summary!F2 -> 25.810924 | D4: =((Inputs!B10*8*2200)-Summary!D2)*Inputs!B19/Summary!F2 -> 35.054622 | E4: =((Inputs!B10*10*2200)-Summary!D2)*Inputs!B19/Summary!F2 -> 44.298319 | F4: =((Inputs!B10*12*2200)-Summary!D2)*Inputs!B19/Summary!F2 -> 53.542017
A5: Manual=2600 | B5: =((Inputs!B10*4*2600)-Summary!D2)*Inputs!B19/Summary!F2 -> 19.928571 | C5: =((Inputs!B10*6*2600)-Summary!D2)*Inputs!B19/Summary!F2 -> 30.852941 | D5: =((Inputs!B10*8*2600)-Summary!D2)*Inputs!B19/Summary!F2 -> 41.777311 | E5: =((Inputs!B10*10*2600)-Summary!D2)*Inputs!B19/Summary!F2 -> 52.701681 | F5: =((Inputs!B10*12*2600)-Summary!D2)*Inputs!B19/Summary!F2 -> 63.62605
A6: Manual=3000 | B6: =((Inputs!B10*4*3000)-Summary!D2)*Inputs!B19/Summary!F2 -> 23.289916 | C6: =((Inputs!B10*6*3000)-Summary!D2)*Inputs!B19/Summary!F2 -> 35.894958 | D6: =((Inputs!B10*8*3000)-Summary!D2)*Inputs!B19/Summary!F2 -> 48.5 | E6: =((Inputs!B10*10*3000)-Summary!D2)*Inputs!B19/Summary!F2 -> 61.105042 | F6: =((Inputs!B10*12*3000)-Summary!D2)*Inputs!B19/Summary!F2 -> 73.710084

Sheet Data Definitions
A1: Field Name | B1: Definition and use(EN) | C1: Definition and use(CN) | D1: Example
A2: 1. Inputs - Input area: select scenario, parameters auto-fill, editable. / 选择场景并带出参数，可手动修改
A3: Scenario selection｜选择场景 | B3: Choose a predefined scenario: Rooftop, C&I, or Utility. | C3: 选择一个预设场景：屋顶分布式、工商业、或大型地面电站。 | D3: 每个场景对应一组默认参数（规模、频次、人工单价等）。切换场景后，其他输入单元格会自动刷新。
A4: Plant size (MW)｜电站规模 | B4: Total installed solar capacity of the plant (in MW). | C4: 电站的总装机容量（兆瓦）。
A5: Cleaning frequency (times/year)｜清洗频次 | B5: Number of cleaning cycles required per year. | C5: 每年需要进行的清洗次数。
A6: Manual cleaning cost (¥/MW per cleaning)｜人工清洗单价 | B6: Average cost of manual cleaning per MW for each cleaning cycle. | C6: 每兆瓦单次人工清洗的平均费用。
A7: Soiling improvement (%)｜污损改善率(%) | B7: Expected efficiency gain (%) after cleaning. | C7: 清洁后预计减少的污损比例（效率提升百分比）。
A8: Electricity price (¥/kWh)｜上网电价 | B8: Average feed-in tariff or electricity selling price. | C8: 平均上网电价或售电单价。
A9: Capacity factor (%)｜容量系数(%) | B9: Ratio of actual annual generation to maximum possible generation (efficiency of the plant). A commonly used metric in the power generation industry, capacity factor = actual power generation (kWh) / installed capacity (kW) × 8,760 hours. Theoretical maximum value: This assumes the power plant operates at full capacity year-round (24 hours x 365 days = 8,760 hours). Actual value: PV power plants are affected by factors such as sunlight, weather, location, and module efficiency, and it's impossible for them to operate at full capacity all the time. Annual power generation = installed capacity (MW) × 1,000 × 8,760 × capacity factor. | C9: 电站实际年发电量与理论最大发电量的比率（发电效率）。 发电行业的常用指标，容量系数=实际发电量（kWh）/装机容量（kW)×8760h 理论最大值：假设电站全年满负荷运转（24小时×365天 = 8760小时）。 实际值：光伏电站受日照、天气、地理位置、组件效率等影响，不可能一直满发。 年发电量：年发电量=装机容量(MW)×1000×8760×容量系数 | D9: 🔹 Typical range: Europe: 12%–20% (Germany and Poland are typically 15–18%) Middle East: 20%–25% (high-sunlight regions like Saudi Arabia and Dubai) North America: 18%–25% (California, Texas, etc.)
A10: Cleaning window per cycle (days)｜每周期施工窗(日) | B10: Maximum number of days allowed to complete one full cleaning cycle. | C10: 每轮清扫允许的施工天数。
A11: Shifts per day (1=single, 2=day+night)｜班次数 | B11: Number of shifts per day (1 = single shift, 2 = day + night). | C11: 每天的班次数（1=单班，2=昼夜双班）。
A12: Redundancy factor (e.g., 1.1)｜冗余系数 | B12: Additional capacity buffer (e.g., 1.1 = +10%) to ensure reliability. | C12: 为保证可靠性增加的能力冗余（如 1.1 表示多配 10%）。
A13: Analysis horizon (years)｜测算年限 | B13: Duration (years) of financial analysis. | C13: 财务测算期（年）。
A15: 2. Devices - Device settings: unit price, efficiency, lifetime, units. / 设备参数：设置不同机器人单价、效率、寿命、数量,系统自动计算单周期总清扫能力（含班次×施工窗×冗余）,判断是否满足项目规模（Adequacy ≥ Plant×冗余）
A16: Enable｜启用 | B16: 1 = include this device in calculation; 0 = ignore. | C16: 1=启用设备计算；0=忽略该设备。
A17: Device｜设备名称 | B17: Type of cleaning device (e.g., Tracked Robot, Bridge/Rail). | C17: 清洁设备类型（如履带式、桥式/轨道）。
A18: Method｜清洁方式 | B18: Cleaning method (Dry, Wet, or both). | C18: 清洁方式（干洗、湿洗或两用）。
A19: Unit price (¥)｜单价 | B19: Robot Purchase price per unit (CAPEX). | C19: 单台设备采购价格（资本支出）。
A20: Capacity (MW/day)｜效率 | B20: Cleaning capacity per day (in MW), this value is different in different scenarios. | C20: 每天可清扫的光伏容量（兆瓦），不同场景设备的清洁能力不同。
A21: Consumable (¥/change)｜耗材单价 | B21: Cost of consumables for one replacement cycle. | C21: 单次耗材更换的费用。
A22: Interval (months)｜更换周期(月) | B22: Consumable replacement interval in months. | C22: 耗材更换周期（月）。
A23: Warranty (¥/year)｜延保/年 | B23: Extended warranty cost per year. | C23: 每年的延保费用。
A24: Lifetime (years)｜寿命(年) | B24: Expected service life of the device. | C24: 设备的使用寿命（年）。
A25: Units｜采购数量 | B25: Number of units purchased. | C25: 采购台数。
A26: 3. Summary - Summary results: annual costs, savings, payback year, ROI. / 汇总结果：年度成本、节省、回本年、ROI
A27: Total capacity per cycle (MW)｜单周期总清扫能力 | B27: EN: The maximum solar capacity (MW) that all selected devices can clean in one cleaning cycle (Cleaning window × Shifts). | C27: CN: 所有选用设备在一个清洁周期内（施工窗口天数 × 班次数）能够覆盖的光伏容量（兆瓦数）。
A28: Adequacy (>= Plant?)｜能力覆盖是否达标 | B28: EN: Whether the cleaning capacity per cycle is sufficient to cover the total plant size (including redundancy factor). | C28: CN: 单周期清扫能力是否能满足电站总规模（含冗余系数）的需求。
A29: Annual manual cost (¥)｜年度人工成本 | B29: EN: Estimated annual cost if cleaning is done entirely by manual labor (Plant size × Frequency × Manual cost per MW). | C29: CN: 如果全部采用人工清洗方式，预计的年度费用（电站规模 × 清洗频次 × 每兆瓦人工成本）。
A30: Annual robot cost (¥)｜年度机器人成本 | B30: EN: The total annualized cost of robots, including depreciation (Unit price ÷ Lifetime), consumables, and extended warranty. | C30: CN: 机器人设备的年度化总成本，包括折旧（单价 ÷ 寿命）、耗材更换费用、以及延保费用。
A31: Annual savings (¥)｜年度节省 | B31: EN: Difference between manual cleaning cost and robot cleaning cost (Manual – Robot). | C31: CN: 与人工清洗相比，使用机器人每年可节省的费用（人工成本 – 机器人成本）。
A32: CAPEX Upfront CAPEX (¥)｜前期投入 | B32: EN: Initial capital expenditure for purchasing all robots (Unit price × Units). | C32: CN: 一次性采购机器人所需的前期资本支出（单价 × 数量）。 | D32: 在你的模型里：CAPEX=∑(每种设备单价×采购数量) CAPEX=∑(每种设备单价×采购数量) 不含日常运维（耗材、延保），这些算在 OPEX（运营支出）。 在财务模型里，CAPEX 会摊销到寿命期（通过折旧或年化成本），但在 回本期计算里，通常作为一次性大额投入和累计节省对比。
A33: Payback year｜回本年 | B33: EN: The first year when cumulative savings exceed initial CAPEX, i.e., when investment is recovered. | C33: CN: 累计节省金额首次超过前期投入的年份，即投资回收期。
A34: ROI over horizon｜投资回报率(测算期) | B34: EN: Return on Investment (ROI) over the analysis horizon: (Cumulative savings – CAPEX) ÷ CAPEX. | C34: CN: 在测算期内的投资回报率： (累计节省 – 前期投入) ÷ 前期投入。
A35: Annual generation (kWh)｜年发电量(估算) | B35: EN: Estimated yearly electricity generation based on plant size and capacity factor. | C35: CN: 根据电站规模和容量系数估算出的年发电量。
A36: Extra revenue from reduced soiling (¥/yr)｜因污损减少的增收/年 | B36: EN: Additional revenue gained by reducing soiling losses, calculated as Annual generation × Electricity price × Soiling improvement %. | C36: CN: 通过减少面板污损带来的额外发电收益，计算公式：年发电量 × 电价 × 污损改善率%。
A37: 4. Yearly - Yearly cash flow: yearly savings, cumulative savings, payback. / 年度现金流：逐年节省、累计节省、回本点
A38: Year｜年 | B38: Sequential year of the analysis period. | C38: 分析期的年份序号。
A39: Manual cost (¥)｜人工成本 | B39: Annual manual cleaning cost (constant each year). | C39: 每年的人工清洗成本（固定值）。
A40: Robot cost (¥)｜机器人成本 | B40: Annualized robot cost (depreciation + consumables + warranty). | C40: 每年的机器人成本（折旧+耗材+延保）。
A41: Annual savings (¥)｜年度节省 | B41: Manual cost – Robot cost. | C41: 人工成本减去机器人成本。
...
